--- Logging error ---
Traceback (most recent call last):
  File "c:\Users\Kirill\AppData\Local\Programs\Python\Python313\Lib\logging\__init__.py", line 1153, in emit
    stream.write(msg + self.terminator)
    ~~~~~~~~~~~~^^^^^^^^^^^^^^^^^^^^^^^
  File "c:\Users\Kirill\AppData\Local\Programs\Python\Python313\Lib\encodings\cp1251.py", line 19, in encode
    return codecs.charmap_encode(input,self.errors,encoding_table)[0]
           ~~~~~~~~~~~~~~~~~~~~~^^^^^^^^^^^^^^^^^^^^^^^^^^^^^^^^^^
UnicodeEncodeError: 'charmap' codec can't encode character '\xd7' in position 88: character maps to <undefined>
Call stack:
  File "c:\Users\Kirill\AppData\Local\Programs\Python\Python313\Lib\runpy.py", line 198, in _run_module_as_main
    return _run_code(code, main_globals, None,
  File "c:\Users\Kirill\AppData\Local\Programs\Python\Python313\Lib\runpy.py", line 88, in _run_code
    exec(code, run_globals)
  File "c:\Users\Kirill\.vscode\extensions\ms-python.debugpy-2025.4.1-win32-x64\bundled\libs\debugpy\launcher/../..\debugpy\__main__.py", line 71, in <module>
    cli.main()
  File "c:\Users\Kirill\.vscode\extensions\ms-python.debugpy-2025.4.1-win32-x64\bundled\libs\debugpy\launcher/../..\debugpy/..\debugpy\server\cli.py", line 501, in main
    run()
  File "c:\Users\Kirill\.vscode\extensions\ms-python.debugpy-2025.4.1-win32-x64\bundled\libs\debugpy\launcher/../..\debugpy/..\debugpy\server\cli.py", line 351, in run_file
    runpy.run_path(target, run_name="__main__")
  File "c:\Users\Kirill\.vscode\extensions\ms-python.debugpy-2025.4.1-win32-x64\bundled\libs\debugpy\_vendored\pydevd\_pydevd_bundle\pydevd_runpy.py", line 310, in run_path
    return _run_module_code(code, init_globals, run_name, pkg_name=pkg_name, script_name=fname)
  File "c:\Users\Kirill\.vscode\extensions\ms-python.debugpy-2025.4.1-win32-x64\bundled\libs\debugpy\_vendored\pydevd\_pydevd_bundle\pydevd_runpy.py", line 127, in _run_module_code
    _run_code(code, mod_globals, init_globals, mod_name, mod_spec, pkg_name, script_name)
  File "c:\Users\Kirill\.vscode\extensions\ms-python.debugpy-2025.4.1-win32-x64\bundled\libs\debugpy\_vendored\pydevd\_pydevd_bundle\pydevd_runpy.py", line 118, in _run_code
    exec(code, run_globals)
  File "C:\Users\Kirill\Desktop\Steps\Try_test\test_main.py", line 274, in <module>
    pytest.main([
  File "c:\Users\Kirill\AppData\Local\Programs\Python\Python313\Lib\site-packages\_pytest\config\__init__.py", line 175, in main
    ret: ExitCode | int = config.hook.pytest_cmdline_main(config=config)
  File "c:\Users\Kirill\AppData\Local\Programs\Python\Python313\Lib\site-packages\pluggy\_hooks.py", line 513, in __call__
    return self._hookexec(self.name, self._hookimpls.copy(), kwargs, firstresult)
  File "c:\Users\Kirill\AppData\Local\Programs\Python\Python313\Lib\site-packages\pluggy\_manager.py", line 120, in _hookexec
    return self._inner_hookexec(hook_name, methods, kwargs, firstresult)
  File "c:\Users\Kirill\AppData\Local\Programs\Python\Python313\Lib\site-packages\pluggy\_callers.py", line 103, in _multicall
    res = hook_impl.function(*args)
  File "c:\Users\Kirill\AppData\Local\Programs\Python\Python313\Lib\site-packages\_pytest\main.py", line 330, in pytest_cmdline_main
    return wrap_session(config, _main)
  File "c:\Users\Kirill\AppData\Local\Programs\Python\Python313\Lib\site-packages\_pytest\main.py", line 283, in wrap_session
    session.exitstatus = doit(config, session) or 0
  File "c:\Users\Kirill\AppData\Local\Programs\Python\Python313\Lib\site-packages\_pytest\main.py", line 337, in _main
    config.hook.pytest_runtestloop(session=session)
  File "c:\Users\Kirill\AppData\Local\Programs\Python\Python313\Lib\site-packages\pluggy\_hooks.py", line 513, in __call__
    return self._hookexec(self.name, self._hookimpls.copy(), kwargs, firstresult)
  File "c:\Users\Kirill\AppData\Local\Programs\Python\Python313\Lib\site-packages\pluggy\_manager.py", line 120, in _hookexec
    return self._inner_hookexec(hook_name, methods, kwargs, firstresult)
  File "c:\Users\Kirill\AppData\Local\Programs\Python\Python313\Lib\site-packages\pluggy\_callers.py", line 103, in _multicall
    res = hook_impl.function(*args)
  File "c:\Users\Kirill\AppData\Local\Programs\Python\Python313\Lib\site-packages\_pytest\main.py", line 362, in pytest_runtestloop
    item.config.hook.pytest_runtest_protocol(item=item, nextitem=nextitem)
  File "c:\Users\Kirill\AppData\Local\Programs\Python\Python313\Lib\site-packages\pluggy\_hooks.py", line 513, in __call__
    return self._hookexec(self.name, self._hookimpls.copy(), kwargs, firstresult)
  File "c:\Users\Kirill\AppData\Local\Programs\Python\Python313\Lib\site-packages\pluggy\_manager.py", line 120, in _hookexec
    return self._inner_hookexec(hook_name, methods, kwargs, firstresult)
  File "c:\Users\Kirill\AppData\Local\Programs\Python\Python313\Lib\site-packages\pluggy\_callers.py", line 103, in _multicall
    res = hook_impl.function(*args)
  File "C:\Users\Kirill\AppData\Local\Programs\Python\Python313\Lib\site-packages\pytest_rerunfailures.py", line 566, in pytest_runtest_protocol
    reports = runtestprotocol(item, nextitem=nextitem, log=False)
  File "c:\Users\Kirill\AppData\Local\Programs\Python\Python313\Lib\site-packages\_pytest\runner.py", line 132, in runtestprotocol
    reports.append(call_and_report(item, "call", log))
  File "c:\Users\Kirill\AppData\Local\Programs\Python\Python313\Lib\site-packages\_pytest\runner.py", line 241, in call_and_report
    call = CallInfo.from_call(
  File "c:\Users\Kirill\AppData\Local\Programs\Python\Python313\Lib\site-packages\_pytest\runner.py", line 341, in from_call
    result: TResult | None = func()
  File "c:\Users\Kirill\AppData\Local\Programs\Python\Python313\Lib\site-packages\_pytest\runner.py", line 242, in <lambda>
    lambda: runtest_hook(item=item, **kwds), when=when, reraise=reraise
  File "c:\Users\Kirill\AppData\Local\Programs\Python\Python313\Lib\site-packages\pluggy\_hooks.py", line 513, in __call__
    return self._hookexec(self.name, self._hookimpls.copy(), kwargs, firstresult)
  File "c:\Users\Kirill\AppData\Local\Programs\Python\Python313\Lib\site-packages\pluggy\_manager.py", line 120, in _hookexec
    return self._inner_hookexec(hook_name, methods, kwargs, firstresult)
  File "c:\Users\Kirill\AppData\Local\Programs\Python\Python313\Lib\site-packages\pluggy\_callers.py", line 103, in _multicall
    res = hook_impl.function(*args)
  File "c:\Users\Kirill\AppData\Local\Programs\Python\Python313\Lib\site-packages\_pytest\runner.py", line 174, in pytest_runtest_call
    item.runtest()
  File "c:\Users\Kirill\AppData\Local\Programs\Python\Python313\Lib\site-packages\_pytest\python.py", line 1627, in runtest
    self.ihook.pytest_pyfunc_call(pyfuncitem=self)
  File "c:\Users\Kirill\AppData\Local\Programs\Python\Python313\Lib\site-packages\pluggy\_hooks.py", line 513, in __call__
    return self._hookexec(self.name, self._hookimpls.copy(), kwargs, firstresult)
  File "c:\Users\Kirill\AppData\Local\Programs\Python\Python313\Lib\site-packages\pluggy\_manager.py", line 120, in _hookexec
    return self._inner_hookexec(hook_name, methods, kwargs, firstresult)
  File "c:\Users\Kirill\AppData\Local\Programs\Python\Python313\Lib\site-packages\pluggy\_callers.py", line 103, in _multicall
    res = hook_impl.function(*args)
  File "c:\Users\Kirill\AppData\Local\Programs\Python\Python313\Lib\site-packages\_pytest\python.py", line 159, in pytest_pyfunc_call
    result = testfunction(**testargs)
  File "C:\Users\Kirill\Desktop\Steps\Try_test\test_main.py", line 124, in test_login
    logger.info(f"Отримано повідомлення: {message.text}")
Message: 'Отримано повідомлення: You logged into a secure area!\n×'
Arguments: ()
